INFO:paramiko110.transport:Connected (version 2.0, client OpenSSH_5.3)
INFO:paramiko110.transport:Authentication (publickey) successful!
INFO:paramiko110.transport:Secsh channel 1 opened.
[ui2.grid.kiae.ru] Executing task 'run_xrdstress'
Traceback (most recent call last):
  File "/usr/lib/python2.6/site-packages/fabric/main.py", line 739, in main
    *args, **kwargs
  File "/usr/lib/python2.6/site-packages/fabric/tasks.py", line 317, in execute
    multiprocessing
  File "/usr/lib/python2.6/site-packages/fabric/tasks.py", line 213, in _execute
    return task.run(*args, **kwargs)
  File "/usr/lib/python2.6/site-packages/fabric/tasks.py", line 123, in run
    return self.wrapped(*args, **kwargs)
  File "/home/virthead/fedtests/fed_test.py", line 33, in run_xrdstress
    upload_template('/tmp/x509up_u500', 'x509up_virthead')
  File "/usr/lib/python2.6/site-packages/fabric/contrib/files.py", line 85, in upload_template
    if func('test -d %s' % _expand_path(destination)).succeeded:
  File "/usr/lib/python2.6/site-packages/fabric/network.py", line 535, in host_prompting_wrapper
    return func(*args, **kwargs)
  File "/usr/lib/python2.6/site-packages/fabric/operations.py", line 1017, in run
    warn_only=warn_only, stdout=stdout, stderr=stderr, timeout=timeout)
  File "/usr/lib/python2.6/site-packages/fabric/operations.py", line 893, in _run_command
    stderr=stderr, timeout=timeout)
  File "/usr/lib/python2.6/site-packages/fabric/operations.py", line 783, in _execute
    worker.raise_if_needed()
  File "/usr/lib/python2.6/site-packages/fabric/thread_handling.py", line 12, in wrapper
    callable(*args, **kwargs)
  File "/usr/lib/python2.6/site-packages/fabric/io.py", line 215, in input_loop
    byte = msvcrt.getch() if win32 else sys.stdin.read(1)
IOError: [Errno 9] Bad file descriptor
Disconnecting from ui2.grid.kiae.ru... done.
Exception in thread err (most likely raised during interpreter shutdown):
Traceback (most recent call last):
  File "/usr/lib64/python2.6/threading.py", line 532, in __bootstrap_inner
  File "/usr/lib64/python2.6/threading.py", line 484, in run
  File "/usr/lib/python2.6/site-packages/fabric/thread_handling.py", line 12, in wrapper
  File "/usr/lib/python2.6/site-packages/fabric/io.py", line 31, in output_loop
  File "/usr/lib/python2.6/site-packages/fabric/io.py", line 83, in loop
<type 'exceptions.AttributeError'>: 'NoneType' object has no attribute 'timeout'
INFO:paramiko110.transport:Connected (version 2.0, client OpenSSH_5.3)
INFO:paramiko110.transport:Authentication (publickey) successful!
INFO:paramiko110.transport:Secsh channel 1 opened.
[ui2.grid.kiae.ru] Executing task 'run_xrdstress'
Traceback (most recent call last):
  File "/usr/lib/python2.6/site-packages/fabric/main.py", line 739, in main
    *args, **kwargs
  File "/usr/lib/python2.6/site-packages/fabric/tasks.py", line 317, in execute
    multiprocessing
  File "/usr/lib/python2.6/site-packages/fabric/tasks.py", line 213, in _execute
    return task.run(*args, **kwargs)
  File "/usr/lib/python2.6/site-packages/fabric/tasks.py", line 123, in run
    return self.wrapped(*args, **kwargs)
  File "/home/virthead/fedtests/fed_test.py", line 33, in run_xrdstress
    upload_template('/tmp/x509up_u500', 'x509up_virthead')
  File "/usr/lib/python2.6/site-packages/fabric/contrib/files.py", line 85, in upload_template
    if func('test -d %s' % _expand_path(destination)).succeeded:
  File "/usr/lib/python2.6/site-packages/fabric/network.py", line 535, in host_prompting_wrapper
    return func(*args, **kwargs)
  File "/usr/lib/python2.6/site-packages/fabric/operations.py", line 1017, in run
    warn_only=warn_only, stdout=stdout, stderr=stderr, timeout=timeout)
  File "/usr/lib/python2.6/site-packages/fabric/operations.py", line 893, in _run_command
    stderr=stderr, timeout=timeout)
  File "/usr/lib/python2.6/site-packages/fabric/operations.py", line 783, in _execute
    worker.raise_if_needed()
  File "/usr/lib/python2.6/site-packages/fabric/thread_handling.py", line 12, in wrapper
    callable(*args, **kwargs)
  File "/usr/lib/python2.6/site-packages/fabric/io.py", line 215, in input_loop
    byte = msvcrt.getch() if win32 else sys.stdin.read(1)
IOError: [Errno 9] Bad file descriptor
Disconnecting from ui2.grid.kiae.ru... done.
